<?xml version="1.0" encoding="utf-8"?>
<!-- This URDF was automatically created by SolidWorks to URDF Exporter! Originally created by Stephen Brawner (brawner@gmail.com) 
     Commit Version: 1.6.0-1-g15f4949  Build Version: 1.6.7594.29634
     For more information, please see http://wiki.ros.org/sw_urdf_exporter 
     created on 2021.8.4
     modified
          2021.8.4:sole frame orientation
     -->
<robot
  name="thmos_urdf">
  <link
    name="base_link">
  </link>
  <link
    name="body">
    <inertial>
      <origin
        xyz="0.063712 -0.00099792 0.019122"
        rpy="0 0 0" />
      <mass
        value="1.3288" />
      <inertia
        ixx="0.0012431"
        ixy="1.3371E-06"
        ixz="-1.2389E-05"
        iyy="0.00066197"
        iyz="-1.1205E-06"
        izz="0.0010861" />
    </inertial>
    <visual>
      <origin
        xyz="0 0 0"
        rpy="0 0 0" />
      <geometry>
        <mesh
          filename="package://thmos_urdf/meshes/body.STL" />
      </geometry>
      <material
        name="">
        <color
          rgba="0.89804 0.91765 0.92941 1" />
      </material>
    </visual>
    <collision>
      <origin
        xyz="0 0 0"
        rpy="0 0 0" />
      <geometry>
        <mesh
          filename="package://thmos_urdf/meshes/body.STL" />
      </geometry>
    </collision>
  </link>
  <joint
    name="base_link_to_body"
    type="fixed">
    <origin
      xyz="-0.069 0.00135 0.043946"
      rpy="0 0 0" />
    <parent
      link="base_link" />
    <child
      link="body" />
    <axis
      xyz="0 0 0" />
    <limit
      lower="-3.14"
      upper="3.14"
      effort="0"
      velocity="0" />
  </joint>
  <link name="imu_frame">
    <inertial>
      <origin rpy="0.0 0.0 0.0" xyz="0.0 0.0 0.0"/>
      <mass value="1e-09"/>
      <inertia ixx="0.0" ixy="0.0" ixz="0.0" iyy="0.0" iyz="0.0" izz="0.0"/>
    </inertial>
  </link>
  <joint
    name="body_to_imu"
    type="fixed">
    <origin
      xyz="0.03 0 0"
      rpy="0 0 0" />
    <parent
      link="body" />
    <child
      link="imu_frame" />
    <axis
      xyz="0 0 1" />
  </joint>
  <link
    name="neck_link">
    <inertial>
      <origin
        xyz="0.000374754017638169 0.00792661238395012 0.0164902287503008"
        rpy="0 0 0" />
      <mass
        value="0.124460960004064" />
      <inertia
        ixx="2.8805042758389E-05"
        ixy="1.06141323333388E-06"
        ixz="9.02985231695641E-11"
        iyy="2.19026103636437E-05"
        iyz="4.01738564732065E-09"
        izz="3.53155714762973E-05" />
    </inertial>
    <visual>
      <origin
        xyz="0 0 0"
        rpy="0 0 0" />
      <geometry>
        <mesh
          filename="package://thmos_urdf/meshes/neck.STL" />
      </geometry>
      <material
        name="">
        <color
          rgba="0.298039215686275 0.298039215686275 0.298039215686275 1" />
      </material>
    </visual>
    <collision>
      <origin
        xyz="0 0 0"
        rpy="0 0 0" />
      <geometry>
        <mesh
          filename="package://thmos_urdf/meshes/neck.STL" />
      </geometry>
    </collision>
  </link>
  <joint
    name="neck"
    type="revolute">
    <origin
      xyz="0.0878 -0.0012 0.085854"
      rpy="0 0 1.5708" />
    <parent
      link="body" />
    <child
      link="neck_link" />
    <axis
      xyz="0 0 1" />
    <limit
      lower="-3.14"
      upper="3.14"
      effort="3"
      velocity="6" />
    <dynamics
      damping="0.3"
      friction="0.83" />
  </joint>
  <link
    name="head_link">
    <inertial>
      <origin
        xyz="0.00105902022003895 0.0355664089714035 -0.0241900224958814"
        rpy="0 0 0" />
      <mass
        value="0.114036124076544" />
      <inertia
        ixx="3.82925395568687E-05"
        ixy="-1.03991053654543E-06"
        ixz="-3.641539852221E-10"
        iyy="2.26332447272469E-05"
        iyz="-9.47293360670022E-11"
        izz="2.74630698086273E-05" />
    </inertial>
    <visual>
      <origin
        xyz="0 0 0"
        rpy="0 0 0" />
      <geometry>
        <mesh
          filename="package://thmos_urdf/meshes/head.STL" />
      </geometry>
      <material
        name="">
        <color
          rgba="0.898039215686275 0.917647058823529 0.929411764705882 1" />
      </material>
    </visual>
    <collision>
      <origin
        xyz="0 0 0"
        rpy="0 0 0" />
      <geometry>
        <mesh
          filename="package://thmos_urdf/meshes/head.STL" />
      </geometry>
    </collision>
  </link>
  <joint
    name="head"
    type="revolute">
    <origin
      xyz="-0.0265 -0.003 0.0172"
      rpy="1.5708 0 -1.5708" />
    <parent
      link="neck_link" />
    <child
      link="head_link" />
    <axis
      xyz="0 0 1" />
    <limit
      lower="-3.14"
      upper="3.14"
      effort="3"
      velocity="6" />
    <dynamics
      damping="0.3"
      friction="0.83" />
  </joint>
  <link name="camera">
    <inertial>
      <origin rpy="0.0 0.0 0.0" xyz="0.0 0.0 0.0"/>
      <mass value="1e-09"/>
      <inertia ixx="0.0" ixy="0.0" ixz="0.0" iyy="0.0" iyz="0.0" izz="0.0"/>
    </inertial>
  </link>
  <joint name="camera_frame" type="fixed">
    <origin rpy="-1.5708 0.0 0.0" xyz="0.0237 0.0395 -0.025"/>
    <axis xyz="0.0 0.0 0.0"/>
    <parent link="head_link"/>
    <child link="camera"/>
  </joint>
  <link name="camera_optical_frame">
    <inertial>
      <origin rpy="0.0 0.0 0.0" xyz="0.0 0.0 0.0"/>
      <mass value="1e-09"/>
      <inertia ixx="0.0" ixy="0.0" ixz="0.0" iyy="0.0" iyz="0.0" izz="0.0"/>
    </inertial>
  </link>
  <joint name="camera_optical_frame_frame" type="fixed">
    <origin rpy="3.14159 -1.5708 0.0" xyz="0.0232 0.0395 -0.025"/>
    <axis xyz="0.0 0.0 0.0"/>
    <parent link="head_link"/>
    <child link="camera_optical_frame"/>
  </joint>
  <link
    name="L_arm_1_link">
    <inertial>
      <origin
        xyz="-0.00270348856091474 -2.98303048928972E-14 0.00912222923452145"
        rpy="0 0 0" />
      <mass
        value="0.0181607936880923" />
      <inertia
        ixx="4.12173986238463E-06"
        ixy="-3.2877850320291E-21"
        ixz="-1.84209426151666E-21"
        iyy="7.89270004328203E-06"
        iyz="-2.93547863189118E-21"
        izz="6.9509203458564E-06" />
    </inertial>
    <visual>
      <origin
        xyz="0 0 0"
        rpy="0 0 0" />
      <geometry>
        <mesh
          filename="package://thmos_urdf/meshes/L_arm_1.STL" />
      </geometry>
      <material
        name="">
        <color
          rgba="0.898039215686275 0.917647058823529 0.929411764705882 1" />
      </material>
    </visual>
    <collision>
      <origin
        xyz="0 0 0"
        rpy="0 0 0" />
      <geometry>
        <mesh
          filename="package://thmos_urdf/meshes/L_arm_1.STL" />
      </geometry>
    </collision>
  </link>
  <joint
    name="L_arm_1"
    type="revolute">
    <origin
      xyz="0.0878 0.08445 0.059554"
      rpy="1.5708 0 -3.1416" />
    <parent
      link="body" />
    <child
      link="L_arm_1_link" />
    <axis
      xyz="0 0 1" />
    <limit
      lower="-3.14"
      upper="3.14"
      effort="3"
      velocity="6" />
    <dynamics
      damping="0.3"
      friction="0.83" />
  </joint>
  <link
    name="L_arm_2_link">
    <inertial>
      <origin
        xyz="-0.0555336258522437 0.000228650195428066 -0.0224177788260872"
        rpy="0 0 0" />
      <mass
        value="0.257261302812499" />
      <inertia
        ixx="4.50171126863418E-05"
        ixy="1.05764403250118E-06"
        ixz="-1.05764403250123E-06"
        iyy="7.00809162267162E-05"
        iyz="1.86757292836393E-10"
        izz="7.25001715326831E-05" />
    </inertial>
    <visual>
      <origin
        xyz="0 0 0"
        rpy="0 0 0" />
      <geometry>
        <mesh
          filename="package://thmos_urdf/meshes/L_arm_2.STL" />
      </geometry>
      <material
        name="">
        <color
          rgba="0.898039215686275 0.917647058823529 0.929411764705882 1" />
      </material>
    </visual>
    <collision>
      <origin
        xyz="0 0 0"
        rpy="0 0 0" />
      <geometry>
        <mesh
          filename="package://thmos_urdf/meshes/L_arm_2.STL" />
      </geometry>
    </collision>
  </link>
  <joint
    name="L_arm_2"
    type="revolute">
    <origin
      xyz="0.0237 0 0.02425"
      rpy="0 1.5708 0" />
    <parent
      link="L_arm_1_link" />
    <child
      link="L_arm_2_link" />
    <axis
      xyz="0 0 1" />
    <limit
      lower="-3.14"
      upper="3.14"
      effort="3"
      velocity="6" />
    <dynamics
      damping="0.3"
      friction="0.83" />
  </joint>
  <link
    name="L_arm_3_link">
    <inertial>
      <origin
        xyz="0.0610691517699158 0.0132650328153034 -0.0146476390287438"
        rpy="0 0 0" />
      <mass
        value="0.0391883327866054" />
      <inertia
        ixx="1.1531973600899E-05"
        ixy="-1.47448079661083E-06"
        ixz="-7.52413264450704E-06"
        iyy="6.36512327134345E-05"
        iyz="2.87923177830407E-08"
        izz="5.98055732184809E-05" />
    </inertial>
    <visual>
      <origin
        xyz="0 0 0"
        rpy="0 0 0" />
      <geometry>
        <mesh
          filename="package://thmos_urdf/meshes/L_arm_3.STL" />
      </geometry>
      <material
        name="">
        <color
          rgba="0.898039215686275 0.917647058823529 0.929411764705882 1" />
      </material>
    </visual>
    <collision>
      <origin
        xyz="0 0 0"
        rpy="0 0 0" />
      <geometry>
        <mesh
          filename="package://thmos_urdf/meshes/L_arm_3.STL" />
      </geometry>
    </collision>
  </link>
  <joint
    name="L_arm_3"
    type="revolute">
    <origin
      xyz="-0.1091 0.0227 -0.0226"
      rpy="1.5708 0 -3.1416" />
    <parent
      link="L_arm_2_link" />
    <child
      link="L_arm_3_link" />
    <axis
      xyz="0 0 -1" />
    <limit
      lower="-3.14"
      upper="3.14"
      effort="3"
      velocity="6" />
    <dynamics
      damping="0.3"
      friction="0.83" />
  </joint>
  <link name="l_wrist">
    <inertial>
      <origin rpy="0.0 0.0 0.0" xyz="0.0 0.0 0.0"/>
      <mass value="1e-09"/>
      <inertia ixx="0.0" ixy="0.0" ixz="0.0" iyy="0.0" iyz="0.0" izz="0.0"/>
    </inertial>
  </link>
  <joint name="l_wrist_frame" type="fixed">
    <origin rpy="0 0 0" xyz="0.15 0 0"/>
    <axis xyz="0.0 0.0 0.0"/>
    <parent link="L_arm_3_link"/>
    <child link="l_wrist"/>
  </joint>
  <link
    name="R_arm_1_link">
    <inertial>
      <origin
        xyz="-0.00270348856095659 -2.15036322082085E-14 -0.0118722292345103"
        rpy="0 0 0" />
      <mass
        value="0.0181607936880923" />
      <inertia
        ixx="4.12173986238461E-06"
        ixy="-6.73547515457905E-20"
        ixz="-3.34992478122145E-21"
        iyy="7.892700043282E-06"
        iyz="1.44907271888797E-21"
        izz="6.95092034585637E-06" />
    </inertial>
    <visual>
      <origin
        xyz="0 0 0"
        rpy="0 0 0" />
      <geometry>
        <mesh
          filename="package://thmos_urdf/meshes/R_arm_1.STL" />
      </geometry>
      <material
        name="">
        <color
          rgba="0.898039215686275 0.917647058823529 0.929411764705882 1" />
      </material>
    </visual>
    <collision>
      <origin
        xyz="0 0 0"
        rpy="0 0 0" />
      <geometry>
        <mesh
          filename="package://thmos_urdf/meshes/R_arm_1.STL" />
      </geometry>
    </collision>
  </link>
  <joint
    name="R_arm_1"
    type="revolute">
    <origin
      xyz="0.0878 -0.08685 0.059554"
      rpy="1.5708 0 3.1416" />
    <parent
      link="body" />
    <child
      link="R_arm_1_link" />
    <axis
      xyz="0 0 -1" />
    <limit
      lower="-3.14"
      upper="3.14"
      effort="3"
      velocity="6" />
    <dynamics
      damping="0.3"
      friction="0.83" />
  </joint>
  <link
    name="R_arm_2_link">
    <inertial>
      <origin
        xyz="0.0555336256974389 0.000228648579194128 -0.0224177804428706"
        rpy="0 0 0" />
      <mass
        value="0.257261343297452" />
      <inertia
        ixx="4.5017126042755E-05"
        ixy="-1.05764222141383E-06"
        ixz="1.05764222141381E-06"
        iyy="7.00809285626232E-05"
        iyz="1.84550114679737E-10"
        izz="7.250018386859E-05" />
    </inertial>
    <visual>
      <origin
        xyz="0 0 0"
        rpy="0 0 0" />
      <geometry>
        <mesh
          filename="package://thmos_urdf/meshes/R_arm_2.STL" />
      </geometry>
      <material
        name="">
        <color
          rgba="0.298039215686275 0.298039215686275 0.298039215686275 1" />
      </material>
    </visual>
    <collision>
      <origin
        xyz="0 0 0"
        rpy="0 0 0" />
      <geometry>
        <mesh
          filename="package://thmos_urdf/meshes/R_arm_2.STL" />
      </geometry>
    </collision>
  </link>
  <joint
    name="R_arm_2"
    type="revolute">
    <origin
      xyz="0.0237 0 -0.027"
      rpy="0 1.5708 0" />
    <parent
      link="R_arm_1_link" />
    <child
      link="R_arm_2_link" />
    <axis
      xyz="0 0 1" />
    <limit
      lower="-3.14"
      upper="3.14"
      effort="3"
      velocity="6" />
    <dynamics
      damping="0.3"
      friction="0.83" />
  </joint>
  <link
    name="R_arm_3_link">
    <inertial>
      <origin
        xyz="-0.0610691517699113 0.0132650328152753 -0.0146476390287803"
        rpy="0 0 0" />
      <mass
        value="0.0391883327866054" />
      <inertia
        ixx="1.15319736008989E-05"
        ixy="1.47448079661004E-06"
        ixz="7.52413264450704E-06"
        iyy="6.36512327134348E-05"
        iyz="2.87923177831431E-08"
        izz="5.98055732184812E-05" />
    </inertial>
    <visual>
      <origin
        xyz="0 0 0"
        rpy="0 0 0" />
      <geometry>
        <mesh
          filename="package://thmos_urdf/meshes/R_arm_3.STL" />
      </geometry>
      <material
        name="">
        <color
          rgba="0.898039215686275 0.917647058823529 0.929411764705882 1" />
      </material>
    </visual>
    <collision>
      <origin
        xyz="0 0 0"
        rpy="0 0 0" />
      <geometry>
        <mesh
          filename="package://thmos_urdf/meshes/R_arm_3.STL" />
      </geometry>
    </collision>
  </link>
  <joint
    name="R_arm_3"
    type="revolute">
    <origin
      xyz="0.1091 0.0227 -0.0226"
      rpy="1.5708 0 -3.1416" />
    <parent
      link="R_arm_2_link" />
    <child
      link="R_arm_3_link" />
    <axis
      xyz="0 0 -1" />
    <limit
      lower="-3.14"
      upper="3.14"
      effort="3"
      velocity="6" />
    <dynamics
      damping="0.3"
      friction="0.83" />
  </joint>
  <link name="r_wrist">
    <inertial>
      <origin rpy="0.0 0.0 0.0" xyz="0.0 0.0 0.0"/>
      <mass value="1e-09"/>
      <inertia ixx="0.0" ixy="0.0" ixz="0.0" iyy="0.0" iyz="0.0" izz="0.0"/>
    </inertial>
  </link>
  <joint name="r_wrist_frame" type="fixed">
    <origin rpy="0 0 0" xyz="-0.15 0 0"/>
    <axis xyz="0.0 0.0 0.0"/>
    <parent link="R_arm_3_link"/>
    <child link="r_wrist"/>
  </joint>
  <link
    name="R_leg_1_link">
    <inertial>
      <origin
        xyz="0.000242896794929587 -0.0148810546825795 -0.0515497640478449"
        rpy="0 0 0" />
      <mass
        value="0.451493328507052" />
      <inertia
        ixx="0.000180898932244134"
        ixy="-2.38369037516758E-06"
        ixz="6.24170041698943E-09"
        iyy="0.000109860138568046"
        iyz="-2.84619940693069E-06"
        izz="0.000172275371244265" />
    </inertial>
    <visual>
      <origin
        xyz="0 0 0"
        rpy="0 0 0" />
      <geometry>
        <mesh
          filename="package://thmos_urdf/meshes/R_leg_1.STL" />
      </geometry>
      <material
        name="">
        <color
          rgba="0.898039215686275 0.917647058823529 0.929411764705882 1" />
      </material>
    </visual>
    <collision>
      <origin
        xyz="0 0 0"
        rpy="0 0 0" />
      <geometry>
        <mesh
          filename="package://thmos_urdf/meshes/R_leg_1.STL" />
      </geometry>
    </collision>
  </link>
  <joint
    name="R_leg_1"
    type="revolute">
    <origin
      xyz="-0.0018 -0.05385 -0.093946"
      rpy="1.5708 0 -1.5708" />
    <parent
      link="body" />
    <child
      link="R_leg_1_link" />
    <axis
      xyz="0 0 1" />
    <limit
      lower="-3.14"
      upper="3.14"
      effort="7"
      velocity="8" />
    <dynamics
      damping="0.66"
      friction="1.42" />
  </joint>
  <link
    name="R_leg_2_link">
    <inertial>
      <origin
        xyz="0.0122194621517914 -0.094313655848584 -0.0282436770621193"
        rpy="0 0 0" />
      <mass
        value="0.255869549056094" />
      <inertia
        ixx="9.82695608187641E-05"
        ixy="4.67521713434423E-06"
        ixz="-1.21264879671056E-10"
        iyy="7.3171187256599E-05"
        iyz="2.17873962694984E-09"
        izz="0.000138459962189222" />
    </inertial>
    <visual>
      <origin
        xyz="0 0 0"
        rpy="0 0 0" />
      <geometry>
        <mesh
          filename="package://thmos_urdf/meshes/R_leg_2.STL" />
      </geometry>
      <material
        name="">
        <color
          rgba="0.898039215686275 0.917647058823529 0.929411764705882 1" />
      </material>
    </visual>
    <collision>
      <origin
        xyz="0 0 0"
        rpy="0 0 0" />
      <geometry>
        <mesh
          filename="package://thmos_urdf/meshes/R_leg_2.STL" />
      </geometry>
    </collision>
  </link>
  <joint
    name="R_leg_2"
    type="revolute">
    <origin
      xyz="0.0281 0.0002095 -0.0739"
      rpy="0 1.5708 0" />
    <parent
      link="R_leg_1_link" />
    <child
      link="R_leg_2_link" />
    <axis
      xyz="0 0 1" />
    <limit
      lower="-3.14"
      upper="3.14"
      effort="7"
      velocity="8" />
    <dynamics
      damping="0.66"
      friction="1.42" />
  </joint>
  <link
    name="R_leg_3_link">
    <inertial>
      <origin
        xyz="0.000341018557630739 -0.0148870721262969 0.0660225553835301"
        rpy="0 0 0" />
      <mass
        value="0.258989867994287" />
      <inertia
        ixx="0.000135250232483748"
        ixy="-2.37925510522261E-06"
        ixz="1.20373969145859E-12"
        iyy="6.84711260250314E-05"
        iyz="3.73535413122895E-07"
        izz="0.00014407344617747" />
    </inertial>
    <visual>
      <origin
        xyz="0 0 0"
        rpy="0 0 0" />
      <geometry>
        <mesh
          filename="package://thmos_urdf/meshes/R_leg_3.STL" />
      </geometry>
      <material
        name="">
        <color
          rgba="0.898039215686275 0.917647058823529 0.929411764705882 1" />
      </material>
    </visual>
    <collision>
      <origin
        xyz="0 0 0"
        rpy="0 0 0" />
      <geometry>
        <mesh
          filename="package://thmos_urdf/meshes/R_leg_3.STL" />
      </geometry>
    </collision>
  </link>
  <joint
    name="R_leg_3"
    type="revolute">
    <origin
      xyz="0 -0.0814 -0.028"
      rpy="1.5708 -1.5708 0" />
    <parent
      link="R_leg_2_link" />
    <child
      link="R_leg_3_link" />
    <axis
      xyz="0 0 -1" />
    <limit
      lower="-3.14"
      upper="3.14"
      effort="7"
      velocity="8" />
    <dynamics
      damping="0.66"
      friction="1.42" />
  </joint>
  <link
    name="R_leg_4_link">
    <inertial>
      <origin
        xyz="0.000633785907184686 -0.0558181596705163 -0.0303382676064725"
        rpy="0 0 0" />
      <mass
        value="0.0679066960076005" />
      <inertia
        ixx="9.59296971630492E-05"
        ixy="9.94737782293033E-07"
        ixz="3.79898249863386E-11"
        iyy="8.33343928808516E-06"
        iyz="-3.34580192882797E-09"
        izz="0.000104160518535864" />
    </inertial>
    <visual>
      <origin
        xyz="0 0 0"
        rpy="0 0 0" />
      <geometry>
        <mesh
          filename="package://thmos_urdf/meshes/R_leg_4.STL" />
      </geometry>
      <material
        name="">
        <color
          rgba="0.898039215686275 0.917647058823529 0.929411764705882 1" />
      </material>
    </visual>
    <collision>
      <origin
        xyz="0 0 0"
        rpy="0 0 0" />
      <geometry>
        <mesh
          filename="package://thmos_urdf/meshes/R_leg_4.STL" />
      </geometry>
    </collision>
  </link>
  <joint
    name="R_leg_4"
    type="revolute">
    <origin
      xyz="0.028 0 0.0747"
      rpy="-1.5708 0 -1.5708" />
    <parent
      link="R_leg_3_link" />
    <child
      link="R_leg_4_link" />
    <axis
      xyz="0 0 1" />
    <limit
      lower="-3.14"
      upper="0.8"
      effort="7"
      velocity="8" />
    <dynamics
      damping="0.66"
      friction="1.42" />
  </joint>
  <link
    name="R_leg_5_link">
    <inertial>
      <origin
        xyz="-0.0282617418943693 0.0165730398465845 -0.0277523989281278"
        rpy="0 0 0" />
      <mass
        value="0.46512114910712" />
      <inertia
        ixx="0.000183362451913054"
        ixy="2.4241321870988E-06"
        ixz="1.44282223201968E-08"
        iyy="0.000120053010159165"
        iyz="2.38710633149706E-06"
        izz="0.00018563013019653" />
    </inertial>
    <visual>
      <origin
        xyz="0 0 0"
        rpy="0 0 0" />
      <geometry>
        <mesh
          filename="package://thmos_urdf/meshes/R_leg_5.STL" />
      </geometry>
      <material
        name="">
        <color
          rgba="0.898039215686275 0.917647058823529 0.929411764705882 1" />
      </material>
    </visual>
    <collision>
      <origin
        xyz="0 0 0"
        rpy="0 0 0" />
      <geometry>
        <mesh
          filename="package://thmos_urdf/meshes/R_leg_5.STL" />
      </geometry>
    </collision>
  </link>
  <joint
    name="R_leg_5"
    type="revolute">
    <origin
      xyz="0.0013624 -0.11999 0"
      rpy="0 0 0" />
    <parent
      link="R_leg_4_link" />
    <child
      link="R_leg_5_link" />
    <axis
      xyz="0 0 1" />
    <limit
      lower="-1.57"
      upper="1.57"
      effort="7"
      velocity="8" />
    <dynamics
      damping="0.66"
      friction="1.42" />
  </joint>
  <link
    name="R_leg_6_link">
    <inertial>
      <origin
        xyz="-7.37902794423206E-13 -0.0185042027856624 0.0278363803698617"
        rpy="0 0 0" />
      <mass
        value="0.0377536385423544" />
      <inertia
        ixx="2.3934318153837E-05"
        ixy="3.46864511941908E-21"
        ixz="-5.66337063104483E-20"
        iyy="2.072219654816E-05"
        iyz="-3.59341385123066E-07"
        izz="9.35507291262461E-06" />
    </inertial>
    <visual>
      <origin
        xyz="0 0 0"
        rpy="0 0 0" />
      <geometry>
        <mesh
          filename="package://thmos_urdf/meshes/R_leg_6.STL" />
      </geometry>
      <material
        name="">
        <color
          rgba="0.898039215686275 0.917647058823529 0.929411764705882 1" />
      </material>
    </visual>
    <collision>
      <origin
        xyz="0 0 0"
        rpy="0 0 0" />
      <geometry>
        <mesh
          filename="package://thmos_urdf/meshes/R_leg_6.STL" />
      </geometry>
    </collision>
  </link>
  <joint
    name="R_leg_6"
    type="revolute">
    <origin
      xyz="-0.0235 0 -0.0279"
      rpy="0 1.5708 0" />
    <parent
      link="R_leg_5_link" />
    <child
      link="R_leg_6_link" />
    <axis
      xyz="0 0 1" />
    <limit
      lower="-1.57"
      upper="1.57"
      effort="7"
      velocity="8" />
    <dynamics
      damping="0.66"
      friction="1.42" />
  </joint>
  <link
    name="r_sole">
    <inertial>
      <origin
        xyz="-0.00533307371632902 -0.00839837846157496 0.00906222619819685"
        rpy="0 0 0" />
      <mass
        value="0.0514108605648368" />
      <inertia
        ixx="3.96695498840741E-05"
        ixy="2.92964387704441E-06"
        ixz="-3.21388348534922E-07"
        iyy="8.16196946411252E-05"
        iyz="-2.16470053766801E-07"
        izz="0.000120318842861491" />
    </inertial>
    <visual>
      <origin
        xyz="0 0 0"
        rpy="0 0 0" />
      <geometry>
        <mesh
          filename="package://thmos_urdf/meshes/r_sole.STL" />
      </geometry>
      <material
        name="">
        <color
          rgba="0.898039215686275 0.917647058823529 0.929411764705882 1" />
      </material>
    </visual>
    <collision>
      <origin
        xyz="0 0 0"
        rpy="0 0 0" />
      <geometry>
        <mesh
          filename="package://thmos_urdf/meshes/r_sole.STL" />
      </geometry>
    </collision>
  </link>
  <joint
    name="r_sole"
    type="fixed">
    <origin
      xyz="0 -0.0455 0.0242"
      rpy="-1.5708 -1.5708 0" />
    <parent
      link="R_leg_6_link" />
    <child
      link="r_sole" />
    <axis
      xyz="0 0 1" />
  </joint>
  <link
    name="L_leg_1_link">
    <inertial>
      <origin
        xyz="-0.000245362191428788 -0.0150511473487731 -0.0510132876308485"
        rpy="0 0 0" />
      <mass
        value="0.446391012900485" />
      <inertia
        ixx="0.000180559948679216"
        ixy="2.37481983527781E-06"
        ixz="6.24170041699285E-09"
        iyy="0.000109521155003129"
        iyz="-2.84620662551416E-06"
        izz="0.000171616568584619" />
    </inertial>
    <visual>
      <origin
        xyz="0 0 0"
        rpy="0 0 0" />
      <geometry>
        <mesh
          filename="package://thmos_urdf/meshes/L_leg_1.STL" />
      </geometry>
      <material
        name="">
        <color
          rgba="0.898039215686275 0.917647058823529 0.929411764705882 1" />
      </material>
    </visual>
    <collision>
      <origin
        xyz="0 0 0"
        rpy="0 0 0" />
      <geometry>
        <mesh
          filename="package://thmos_urdf/meshes/L_leg_1.STL" />
      </geometry>
    </collision>
  </link>
  <joint
    name="L_leg_1"
    type="revolute">
    <origin
      xyz="-0.0018 0.05115 -0.093946"
      rpy="1.5708 0 -1.5708" />
    <parent
      link="body" />
    <child
      link="L_leg_1_link" />
    <axis
      xyz="0 0 1" />
    <limit
      lower="-3.14"
      upper="3.14"
      effort="7"
      velocity="8" />
    <dynamics
      damping="0.66"
      friction="1.42" />
  </joint>
  <link
    name="L_leg_2_link">
    <inertial>
      <origin
        xyz="0.0122194621517911 -0.0943136558485842 0.0282446604041767"
        rpy="0 0 0" />
      <mass
        value="0.255869549056095" />
      <inertia
        ixx="9.82695608187643E-05"
        ixy="4.67521713434429E-06"
        ixz="1.14046296200095E-10"
        iyy="7.31711872565992E-05"
        iyz="-2.17633214789903E-09"
        izz="0.000138459962189222" />
    </inertial>
    <visual>
      <origin
        xyz="0 0 0"
        rpy="0 0 0" />
      <geometry>
        <mesh
          filename="package://thmos_urdf/meshes/L_leg_2.STL" />
      </geometry>
      <material
        name="">
        <color
          rgba="0.898039215686275 0.917647058823529 0.929411764705882 1" />
      </material>
    </visual>
    <collision>
      <origin
        xyz="0 0 0"
        rpy="0 0 0" />
      <geometry>
        <mesh
          filename="package://thmos_urdf/meshes/L_leg_2.STL" />
      </geometry>
    </collision>
  </link>
  <joint
    name="L_leg_2"
    type="revolute">
    <origin
      xyz="-0.0281 0.0002095 -0.0739"
      rpy="0 1.5708 0" />
    <parent
      link="L_leg_1_link" />
    <child
      link="L_leg_2_link" />
    <axis
      xyz="0 0 -1" />
    <limit
      lower="-3.14"
      upper="3.14"
      effort="7"
      velocity="8" />
    <dynamics
      damping="0.66"
      friction="1.42" />
  </joint>
  <link
    name="L_leg_3_link">
    <inertial>
      <origin
        xyz="-0.000341018557628983 -0.0148870721262879 0.0660225566076256"
        rpy="0 0 0" />
      <mass
        value="0.258989867994287" />
      <inertia
        ixx="0.000135250232483748"
        ixy="2.37925510522271E-06"
        ixz="1.2037396792554E-12"
        iyy="6.84711260250314E-05"
        iyz="3.73528194540519E-07"
        izz="0.00014407344617747" />
    </inertial>
    <visual>
      <origin
        xyz="0 0 0"
        rpy="0 0 0" />
      <geometry>
        <mesh
          filename="package://thmos_urdf/meshes/L_leg_3.STL" />
      </geometry>
      <material
        name="">
        <color
          rgba="0.898039215686275 0.917647058823529 0.929411764705882 1" />
      </material>
    </visual>
    <collision>
      <origin
        xyz="0 0 0"
        rpy="0 0 0" />
      <geometry>
        <mesh
          filename="package://thmos_urdf/meshes/L_leg_3.STL" />
      </geometry>
    </collision>
  </link>
  <joint
    name="L_leg_3"
    type="revolute">
    <origin
      xyz="0 -0.0814 0.028"
      rpy="1.5708 -1.5708 0" />
    <parent
      link="L_leg_2_link" />
    <child
      link="L_leg_3_link" />
    <axis
      xyz="0 0 -1" />
    <limit
      lower="-3.14"
      upper="3.14"
      effort="7"
      velocity="8" />
    <dynamics
      damping="0.66"
      friction="1.42" />
  </joint>
  <link
    name="L_leg_4_link">
    <inertial>
      <origin
        xyz="-0.000633785905071904 -0.0558181596640658 -0.0303382676066239"
        rpy="0 0 0" />
      <mass
        value="0.0679066960076005" />
      <inertia
        ixx="9.59296971630492E-05"
        ixy="-9.94737782295072E-07"
        ixz="-3.79898249854746E-11"
        iyy="8.33343928808522E-06"
        iyz="-3.34580192855207E-09"
        izz="0.000104160518535864" />
    </inertial>
    <visual>
      <origin
        xyz="0 0 0"
        rpy="0 0 0" />
      <geometry>
        <mesh
          filename="package://thmos_urdf/meshes/L_leg_4.STL" />
      </geometry>
      <material
        name="">
        <color
          rgba="0.898039215686275 0.917647058823529 0.929411764705882 1" />
      </material>
    </visual>
    <collision>
      <origin
        xyz="0 0 0"
        rpy="0 0 0" />
      <geometry>
        <mesh
          filename="package://thmos_urdf/meshes/L_leg_4.STL" />
      </geometry>
    </collision>
  </link>
  <joint
    name="L_leg_4"
    type="revolute">
    <origin
      xyz="-0.028 0 0.0747"
      rpy="-1.5708 0 1.5708" />
    <parent
      link="L_leg_3_link" />
    <child
      link="L_leg_4_link" />
    <axis
      xyz="0 0 1" />
    <limit
      lower="-0.8"
      upper="3.14"
      effort="7"
      velocity="8" />
    <dynamics
      damping="0.66"
      friction="1.42" />
  </joint>
  <link
    name="L_leg_5_link">
    <inertial>
      <origin
        xyz="0.028261737172733 0.0165730438182495 -0.0277523947860534"
        rpy="0 0 0" />
      <mass
        value="0.465121268031797" />
      <inertia
        ixx="0.000183362498112273"
        ixy="-2.42413431860746E-06"
        ixz="-1.4422230534791E-08"
        iyy="0.000120053046528023"
        iyz="2.38711645911282E-06"
        izz="0.000185630144557586" />
    </inertial>
    <visual>
      <origin
        xyz="0 0 0"
        rpy="0 0 0" />
      <geometry>
        <mesh
          filename="package://thmos_urdf/meshes/L_leg_5.STL" />
      </geometry>
      <material
        name="">
        <color
          rgba="0.898039215686275 0.917647058823529 0.929411764705882 1" />
      </material>
    </visual>
    <collision>
      <origin
        xyz="0 0 0"
        rpy="0 0 0" />
      <geometry>
        <mesh
          filename="package://thmos_urdf/meshes/L_leg_5.STL" />
      </geometry>
    </collision>
  </link>
  <joint
    name="L_leg_5"
    type="revolute">
    <origin
      xyz="-0.0013624 -0.11999 0"
      rpy="0 0 0" />
    <parent
      link="L_leg_4_link" />
    <child
      link="L_leg_5_link" />
    <axis
      xyz="0 0 1" />
    <limit
      lower="-1.57"
      upper="1.57"
      effort="7"
      velocity="8" />
    <dynamics
      damping="0.66"
      friction="1.42" />
  </joint>
  <link
    name="L_leg_6_link">
    <inertial>
      <origin
        xyz="-2.9739405382756E-13 -0.0185042027862403 -0.0278363803720922"
        rpy="0 0 0" />
      <mass
        value="0.0377536385423544" />
      <inertia
        ixx="2.3934318153837E-05"
        ixy="-2.4208018318729E-20"
        ixz="1.22627561245203E-19"
        iyy="2.072219654816E-05"
        iyz="3.59341385122398E-07"
        izz="9.35507291262458E-06" />
    </inertial>
    <visual>
      <origin
        xyz="0 0 0"
        rpy="0 0 0" />
      <geometry>
        <mesh
          filename="package://thmos_urdf/meshes/L_leg_6.STL" />
      </geometry>
      <material
        name="">
        <color
          rgba="0.898039215686275 0.917647058823529 0.929411764705882 1" />
      </material>
    </visual>
    <collision>
      <origin
        xyz="0 0 0"
        rpy="0 0 0" />
      <geometry>
        <mesh
          filename="package://thmos_urdf/meshes/L_leg_6.STL" />
      </geometry>
    </collision>
  </link>
  <joint
    name="L_leg_6"
    type="revolute">
    <origin
      xyz="0.0235 0 -0.0279"
      rpy="0 1.5708 0" />
    <parent
      link="L_leg_5_link" />
    <child
      link="L_leg_6_link" />
    <axis
      xyz="0 0 -1" />
    <limit
      lower="-3.14"
      upper="3.14"
      effort="7"
      velocity="8" />
    <dynamics
      damping="0.66"
      friction="1.42" />
  </joint>
  <link
    name="l_sole">
    <inertial>
      <origin
        xyz="-0.00533307371405239 0.00839837846181375 0.0090622261980815"
        rpy="0 0 0" />
      <mass
        value="0.051410860564837" />
      <inertia
        ixx="3.96695498840741E-05"
        ixy="-2.92964387704452E-06"
        ixz="-3.21388348534851E-07"
        iyy="8.16196946411257E-05"
        iyz="2.16470053766815E-07"
        izz="0.000120318842861491" />
    </inertial>
    <visual>
      <origin
        xyz="0 0 0"
        rpy="0 0 0" />
      <geometry>
        <mesh
          filename="package://thmos_urdf/meshes/l_sole.STL" />
      </geometry>
      <material
        name="">
        <color
          rgba="0.898039215686275 0.917647058823529 0.929411764705882 1" />
      </material>
    </visual>
    <collision>
      <origin
        xyz="0 0 0"
        rpy="0 0 0" />
      <geometry>
        <mesh
          filename="package://thmos_urdf/meshes/l_sole.STL" />
      </geometry>
    </collision>
  </link>
  <joint
    name="l_sole"
    type="fixed">
    <origin
      xyz="0 -0.0455 -0.0242"
      rpy="-1.5708 1.5708 0" />
    <parent
      link="L_leg_6_link" />
    <child
      link="l_sole" />
    <axis
      xyz="0 0 1" />
  </joint>
</robot>